Workbook

Sheet 📊 Dashboard
B1: 📋 ORNET HomeLab — Tableau de Bord Formation 2026
B2: Démarrage : 12 mai 2026 · Sans ISE · Sans WiFi 7/8 · Mise à jour automatique via formules
B3: Tâches Complétées | E3: Tâches Totales | H3: Progression % | K3: Score Moyen /10 | M3: Semaine En cours
B4: =COUNTIF('📅 Plan Tâches'!H:H,"✓") | E4: =COUNTA('📅 Plan Tâches'!F2:F500)-1 | H4: =IFERROR(ROUND(COUNTIF('📅 Plan Tâches'!H:H,"✓")/MAX(COUNTA('📅 Plan Tâches'!F2:F500)-1,1)*100,0)&"%","0%") | K4: =IFERROR(ROUND(AVERAGE('📊 Semaines'!E2:E50),1),"─") | M4: =IFERROR(VLOOKUP(TODAY(),'📊 Semaines'!B2:B50,1,1),"─")
B8: 📅 SUIVI SEMAINES — PROGRESSION
B9: Semaine | C9: Dates | D9: Objectif | E9: T. Réalisées | F9: T. Totales | G9: % Taux | H9: Score /10 | I9: Statut | J9: ✅
B10: S1 — 12-18 mai | C10: 12-18 mai | D10: Setup HomeLab · Python · Morning Agent | E10: 0 | F10: 21 | G10: =IFERROR(ROUND(E10/F10*100,0)&"%","─") | I10: 🔴 À faire | J10: ☐
B11: S2 — 19-25 mai | C11: 19-25 mai | D11: NumPy/Pandas · SSH · CatC API · LI post #1 | E11: 0 | F11: 21 | G11: =IFERROR(ROUND(E11/F11*100,0)&"%","─") | I11: 🔴 À faire | J11: ☐
B12: S3 — 26 mai-1 juin | C12: 26 mai-1 juin | D12: LangChain · Docker · Endpoint /analyze | E12: 0 | F12: 21 | G12: =IFERROR(ROUND(E12/F12*100,0)&"%","─") | I12: 🔴 À faire | J12: ☐
B13: S4 — 2-8 juin | C13: 2-8 juin | D13: scikit-learn · nginx · Bubble.io | E13: 0 | F13: 21 | G13: =IFERROR(ROUND(E13/F13*100,0)&"%","─") | I13: 🔴 À faire | J13: ☐
B14: S5 — 9-15 juin | C14: 9-15 juin | D14: RAG · Docker prod · 5 beta · 1er client 🎯 | E14: 0 | F14: 21 | G14: =IFERROR(ROUND(E14/F14*100,0)&"%","─") | I14: 🔴 À faire | J14: ☐
B15: S6 — 16-22 juin | C15: 16-22 juin | D15: Ansible · 3 clients · API partenaires | E15: 0 | F15: 21 | G15: =IFERROR(ROUND(E15/F15*100,0)&"%","─") | I15: 🔴 À faire | J15: ☐
B16: Juillet | C16: 23 juin-20 juil | D16: Agents IA · 8 clients · Web beta | E16: 0 | F16: 40 | G16: =IFERROR(ROUND(E16/F16*100,0)&"%","─") | I16: 🔴 À faire | J16: ☐
B17: Août | C17: 21 juil-23 août | D17: LLM RF · 10 clients · Vacances | E17: 0 | F17: 30 | G17: =IFERROR(ROUND(E17/F17*100,0)&"%","─") | I17: 🔴 À faire | J17: ☐
B18: Septembre | C18: 25 août-27 sept | D18: MLOps · 12 clients · Bilan Q3 | E18: 0 | F18: 30 | G18: =IFERROR(ROUND(E18/F18*100,0)&"%","─") | I18: 🔴 À faire | J18: ☐
B19: Octobre | C19: 28 sept-25 oct | D19: WifiAudit v2 · 13 clients | E19: 0 | F19: 28 | G19: =IFERROR(ROUND(E19/F19*100,0)&"%","─") | I19: 🔴 À faire | J19: ☐
B20: Novembre | C20: 26 oct-22 nov | D20: 15 clients 🎯 · Plan 2027 · Webinar | E20: 0 | F20: 28 | G20: =IFERROR(ROUND(E20/F20*100,0)&"%","─") | I20: 🔴 À faire | J20: ☐
B21: Décembre | C21: 23 nov-31 déc | D21: Bilan annuel · Repos ⛄ | E21: 0 | F21: 20 | G21: =IFERROR(ROUND(E21/F21*100,0)&"%","─") | I21: 🔴 À faire | J21: ☐
B24: 🚀 KPIs BUSINESS — WIFIAUDIT AI
B25: Indicateur | D25: Objectif | F25: Réalisé | H25: Écart | J25: Statut
B26: Clients WifiAudit payants | D26: 15 | F26: 0 | H26: =F26-D26 | J26: 🔴
B27: Waitlist signups | D27: 20 | F27: 0 | H27: =F27-D27 | J27: 🔴
B28: Posts LinkedIn / mois | D28: 8 | F28: 0 | H28: =F28-D28 | J28: 🔴
B29: Jours sport / mois | D29: 25 | F29: 0 | H29: =F29-D29 | J29: 🔴
B30: Articles or-net.com publiés | D30: 2/mois | F30: 0 | H30: ─ | J30: 🔴
B31: Score semaine moyen | D31: > 7 | F31: 0 | H31: ─ | J31: 🔴
B32: Revenus WifiAudit (€/mois) | D32: 4 485 | F32: 0 | H32: =F32-D32 | J32: 🔴

Sheet 📅 Plan Tâches
A1: 📅 ORNET HomeLab — Plan Tâches Détaillé · Cocher ✓ dans colonne H quand terminé
A2: Date | B2: Jour | C2: S# | D2: Créneau | E2: Segment | F2: Tâche / Description | G2: Livrable attendu | H2: ✅ Fait | I2: Score /5 | J2: Durée | K2: Notes
A3: ━━━ SEMAINE 1 ━━━
A4: 12/05/26 | B4: Mar | C4: 1 | D4: 🏃 Sport | E4: ─ | F4: Cardio 30 min — démarrage formation | G4: ─ | H4: ✗ | I4: ─ | J4: 30 min
A5: 12/05/26 | B5: Mar | C5: 1 | D5: 📚 Matin | E5: Linux | F5: Setup environnement HomeLab — Ubuntu, dossiers, script setup_homelab.sh | G5: setup_homelab.sh fonctionnel + structure dossiers créée | H5: ✗ | I5: ─ | J5: 1h30
A6: 12/05/26 | B6: Mar | C6: 1 | D6: 🔧 Soir 1 | E6: WifiAudit SaaS | F6: Inventaire exports CatC et WLC 9800 disponibles — définir 10 métriques RF | G6: Doc Notion : spec données input v0.1 | H6: ✗ | I6: ─ | J6: 1h30
A7: 12/05/26 | B7: Mar | C7: 1 | D7: 🚀 Soir 2 | E7: WifiAudit SaaS | F7: Architecture backend — FastAPI + Claude API + PDF + PostgreSQL | G7: Diagramme architecture WifiAudit v0.1 | H7: ✗ | I7: ─ | J7: 1h15
A8: 13/05/26 | B8: Mer | C8: 1 | D8: 🏃 Sport | E8: ─ | F8: Stretching + 20 min marche rapide | G8: ─ | H8: ✗ | I8: ─ | J8: 30 min
A9: 13/05/26 | B9: Mer | C9: 1 | D9: 📚 Matin | E9: NoCode/n8n | F9: n8n audit + Morning Agent v0.1 — Trigger 5h45 → Claude → brief → Telegram | G9: Morning Agent v0.1 fonctionnel | H9: ✗ | I9: ─ | J9: 1h30
A10: 13/05/26 | B10: Mer | C10: 1 | D10: 🔧 Soir 1 | E10: ORNET Business | F10: Catalogue 6 offres ORNET avec pricing — Oracle Business setup | G10: Catalogue offres v0.1 dans Notion | H10: ✗ | I10: ─ | J10: 1h30
A11: 13/05/26 | B11: Mer | C11: 1 | D11: 🚀 Soir 2 | E11: ORNET Business | F11: 6 modèles de devis Oracle — conditions paiement + relances auto | G11: 6 modèles devis opérationnels dans Oracle | H11: ✗ | I11: ─ | J11: 1h15
A12: 14/05/26 | B12: Jeu | C12: 1 | D12: 🏃 Sport | E12: ─ | F12: Course 30 min | G12: ─ | H12: ✗ | I12: ─ | J12: 30 min
A13: 14/05/26 | B13: Jeu | C13: 1 | D13: 📚 Matin | E13: LinkedIn | F13: Stratégie contenu mai-juin — post #1 : Python et Network Architect | G13: Post #1 prêt + image PNG | H13: ✗ | I13: ─ | J13: 1h30
A14: 14/05/26 | B14: Jeu | C14: 1 | D14: 🔧 Soir 1 | E14: WifiAudit SaaS | F14: parse_catc_export.py — extraire AP/SSID/canal/RSSI/SNR/clients | G14: Script fonctionnel sur vrai export CatC | H14: ✗ | I14: ─ | J14: 1h30
A15: 14/05/26 | B15: Jeu | C15: 1 | D15: 🚀 Soir 2 | E15: WifiAudit SaaS | F15: Rapport PDF structure — ReportLab template couverture + sections | G15: template_rapport_wifiaudit.pdf généré | H15: ✗ | I15: ─ | J15: 1h15
... A24: 17/05/26 | B24: Dim | C24: 1 | D24: ─ | E24: ─ | F24: PLAN SEMAINE 2 DÉTAILLÉ — préparer ressources | G24: Planning S2 prêt | H24: ✗ | I24: ─ | J24: 1h15
A25: ━━━ SEMAINE 2 ━━━
A26: 19/05/26 | B26: Lun | C26: 2 | D26: 🏃 Sport | E26: ─ | F26: Cardio 30 min | G26: ─ | H26: ✗ | I26: ─ | J26: 30 min
A27: 19/05/26 | B27: Lun | C27: 2 | D27: 📚 Matin | E27: IA/ML | F27: Python fondamentaux — venv, NumPy, Pandas, notebook 01_python_bases.ipynb | G27: notebook + fonction parse_csv_data() testée | H27: ✗ | I27: ─ | J27: 1h30
A28: 19/05/26 | B28: Lun | C28: 2 | D28: 🔧 Soir 1 | E28: Réseau CatC | F28: CatC API — GET /site + /network-device · catc_test.py fonctionnel | G28: catc_test.py avec token d'authentification | H28: ✗ | I28: ─ | J28: 1h30
A29: 19/05/26 | B29: Lun | C29: 2 | D29: 🚀 Soir 2 | E29: Réseau CatC | F29: CatC Wireless Assurance — mapper KPIs → colonnes WifiAudit | G29: Tableau mapping dans Notion | H29: ✗ | I29: ─ | J29: 1h15
A30: 20/05/26 | B30: Mar | C30: 2 | D30: 🏃 Sport | E30: ─ | F30: Course 30 min | G30: ─ | H30: ✗ | I30: ─ | J30: 30 min
A31: 20/05/26 | B31: Mar | C31: 2 | D31: 📚 Matin | E31: Linux | F31: SSH ed25519 + config ~/.ssh/config + sécurisation + script secure_ssh.sh | G31: Accès SSH sécurisé VPS fonctionnel | H31: ✗ | I31: ─ | J31: 1h30
A32: 20/05/26 | B32: Mar | C32: 2 | D32: 🔧 Soir 1 | E32: WifiAudit SaaS | F32: Algorithmes scoring RF — score_rf_metrics() Python testé sur données réelles | G32: Fonction scoring testée + valeurs de référence | H32: ✗ | I32: ─ | J32: 1h30
A33: 20/05/26 | B33: Mar | C33: 2 | D33: 🚀 Soir 2 | E33: WifiAudit SaaS | F33: Entretien validation #1 prep — guide 15 questions + contact prospect | G33: Guide prêt + call planifié | H33: ✗ | I33: ─ | J33: 1h15
A34: 21/05/26 | B34: Mer | C34: 2 | D34: 🏃 Sport | E34: ─ | F34: Vélo 30 min | G34: ─ | H34: ✗ | I34: ─ | J34: 30 min
A35: 21/05/26 | B35: Mer | C35: 2 | D35: 📚 Matin | E35: NoCode/n8n | F35: Morning Agent v0.2 — image LinkedIn via Pillow + validation Romaric | G35: Morning Agent v0.2 avec génération image | H35: ✗ | I35: ─ | J35: 1h30
A36: 21/05/26 | B36: Mer | C36: 2 | D36: 🔧 Soir 1 | E36: ORNET Business | F36: Présentation Gamma ORNET 10 slides — Problème/Solution/Services/Prix | G36: Deck Gamma finalisé et partageable | H36: ✗ | I36: ─ | J36: 1h30
A37: 21/05/26 | B37: Mer | C37: 2 | D37: 🚀 Soir 2 | E37: ORNET Business | F37: Pipeline commercial Notion — 20 premiers prospects importés | G37: CRM léger Notion opérationnel | H37: ✗ | I37: ─ | J37: 1h15
... A48: 25/05/26 | B48: Dim | C48: 2 | D48: ─ | E48: ─ | F48: REVUE SEMAINE 2 — score, post LI #1 retours, rapport PDF qualité | G48: Tracker Notion mis à jour | H48: ✗ | I48: ─ | J48: 30 min
A49: ━━━ SEMAINE 3 ━━━
A50: 26/05/26 | B50: Lun | C50: 3 | D50: 📚 Matin | E50: IA/ML | F50: NumPy + Pandas — analyse 100 APs CatC, histogrammes RSSI/SNR | G50: notebook 02_numpy_pandas.ipynb complet | H50: ✗ | I50: ─ | J50: 1h30
A51: 26/05/26 | B51: Lun | C51: 3 | D51: 🔧 Soir 1 | E51: Réseau CatC | F51: catc_full_inventory.py — APs/clients/SSIDs + gestion token refresh | G51: Inventaire complet CSV + JSON | H51: ✗ | I51: ─ | J51: 1h30
A52: 26/05/26 | B52: Lun | C52: 3 | D52: 🚀 Soir 2 | E52: Réseau CatC | F52: SD-Access Phase 1 lab EVE-NG — topologie + LISP/BGP | G52: Fabric de base opérationnelle en lab | H52: ✗ | I52: ─ | J52: 1h15
A53: 27/05/26 | B53: Mar | C53: 3 | D53: 📚 Matin | E53: Linux | F53: Docker install + Dockerfile WifiAudit — build + run fonctionnel | G53: Dockerfile + image Docker WifiAudit | H53: ✗ | I53: ─ | J53: 1h30
A54: 27/05/26 | B54: Mar | C54: 3 | D54: 🔧 Soir 1 | E54: WifiAudit SaaS | F54: Endpoint /analyze asynchrone — FastAPI BackgroundTasks + job_id | G54: Pipeline upload→analyze asynchrone OK | H54: ✗ | I54: ─ | J54: 1h30
A55: 27/05/26 | B55: Mar | C55: 3 | D55: 🚀 Soir 2 | E55: WifiAudit SaaS | F55: Entretien validation #2 — 30-45 min, focus pricing | G55: Retours documentés | H55: ✗ | I55: ─ | J55: 1h15
A56: 28/05/26 | B56: Mer | C56: 3 | D56: 📚 Matin | E56: NoCode/n8n | F56: Webhook WifiAudit n8n — upload→analyze→rapport PDF→email client | G56: Pipeline entier upload→email automatique | H56: ✗ | I56: ─ | J56: 1h30
A57: 28/05/26 | B57: Mer | C57: 3 | D57: 🔧 Soir 1 | E57: ORNET Business | F57: Cas client #1 anonymisé PDF — FlexConnect migration résultats | G57: Document PDF 1 page prêt à partager | H57: ✗ | I57: ─ | J57: 1h30
A58: 29/05/26 | B58: Jeu | C58: 3 | D58: 📚 Matin | E58: LinkedIn | F58: Publier post #2 + planning juin (8 posts) + post #3 rédaction | G58: Post #2 live + planning juin dans Notion | H58: ✗ | I58: ─ | J58: 1h30
...

Sheet 📊 Semaines
A1: 📊 OBJECTIFS & BILANS SEMAINES · À remplir chaque dimanche soir
A2: S# | B2: Semaine | C2: Dates | D2: Objectif principal | E2: Livrables clés (top 4) | F2: T. Réalisées | G2: T. Totales | H2: % Taux | I2: Score /10 | J2: ✅ OK | K2: Top 3 apprentissages | L2: Blocages + Actions
A3: 1 | B3: S1 — 12 au 18 mai | C3: 12-18 mai | D3: Setup HomeLab · Python bases · Morning Agent v0.1 | E3: setup_homelab.sh · 01_python_bases.ipynb · Morning Agent v0.1 · Archi WifiAudit | F3: 0 | G3: 21 | H3: =IFERROR(ROUND(F3/G3*100,0)&"%","─") | J3: ☐
A4: 2 | B4: S2 — 19 au 25 mai | C4: 19-25 mai | D4: NumPy/Pandas · SSH · CatC API · Scoring RF · Post LI #1 | E4: catc_test.py · score_rf_metrics() · Post LinkedIn #1 · Entretien #1 | F4: 0 | G4: 21 | H4: =IFERROR(ROUND(F4/G4*100,0)&"%","─") | J4: ☐
A5: 3 | B5: S3 — 26 mai-1 juin | C5: 26 mai-1 juin | D5: LangChain · Docker · n8n webhooks · Rapport PDF | E5: catc_full_inventory.py · Dockerfile · endpoint /analyze · 3 pages or-net | F5: 0 | G5: 21 | H5: =IFERROR(ROUND(F5/G5*100,0)&"%","─") | J5: ☐
A6: 4 | B6: S4 — 2 au 8 juin | C6: 2-8 juin | D6: scikit-learn · nginx HTTPS · Bubble.io · Or-net.com live | E6: Modèle ML >70% · API HTTPS · Interface upload · Or-net.com refonte live | F6: 0 | G6: 21 | H6: =IFERROR(ROUND(F6/G6*100,0)&"%","─") | J6: ☐
A7: 5 | B7: S5 — 9 au 15 juin | C7: 9-15 juin | D7: LangChain RAG · Docker prod · 5 beta · PREMIER CLIENT | E7: RAG WifiAudit · Stack prod VPS · 5 beta users · Stripe · Premier revenu 🎯 | F7: 0 | G7: 21 | H7: =IFERROR(ROUND(F7/G7*100,0)&"%","─") | J7: ☐
A8: 6 | B8: S6 — 16 au 22 juin | C8: 16-22 juin | D8: Ansible · 3 clients · API partenaires · Blog #1 | E8: Ansible deploy.yml · 3 clients payants · API partenaires v0.1 · Article blog live | F8: 0 | G8: 21 | H8: =IFERROR(ROUND(F8/G8*100,0)&"%","─") | J8: ☐
A9: 7-10 | B9: S7-10 — Juillet | C9: 23 juin-20 juil | D9: Agents IA WiFi · 8 clients · Interface web beta | E9: Agent IA WiFi v0.1 · Interface web beta · 8 clients · Partenariat | F9: 0 | G9: 40 | H9: =IFERROR(ROUND(F9/G9*100,0)&"%","─") | J9: ☐
A10: 11-14 | B10: S11-14 — Août | C10: 21 juil-23 août | D10: LLM RF · 10 clients · Vacances | E10: Modèle ML anomalie RF · Multi-tenants · 10 clients · Repos | F10: 0 | G10: 30 | H10: =IFERROR(ROUND(F10/G10*100,0)&"%","─") | J10: ☐
A11: 15-18 | B11: S15-18 — Sept | C11: 25 août-27 sept | D11: MLOps · 12 clients · Bilan Q3 | E11: MLflow tracking · API sécurisée · 12 clients · Plan Q4 validé | F11: 0 | G11: 30 | H11: =IFERROR(ROUND(F11/G11*100,0)&"%","─") | J11: ☐
A12: 19-22 | B12: S19-22 — Oct | C12: 28 sept-25 oct | D12: WifiAudit v2 · MLOps prod · 13 clients | E12: WifiAudit v2.0 · ML avancé trames · 13 clients · Monitoring prod | F12: 0 | G12: 28 | H12: =IFERROR(ROUND(F12/G12*100,0)&"%","─") | J12: ☐
A13: 23-26 | B13: S23-26 — Nov | C13: 26 oct-22 nov | D13: 15 clients 🎯 · Plan 2027 · Webinar LI | E13: 15 clients WifiAudit ✅ · Plan 2027 rédigé · Webinar · API partenaires v1.0 | F13: 0 | G13: 28 | H13: =IFERROR(ROUND(F13/G13*100,0)&"%","─") | J13: ☐
A14: 27-31 | B14: S27-31 — Déc | C14: 23 nov-31 déc | D14: Bilan annuel · Offres 2027 · Repos ⛄ | E14: Bilan complet · Post LinkedIn 2026 · Catalogue 2027 · Plan formation 2027 | F14: 0 | G14: 20 | H14: =IFERROR(ROUND(F14/G14*100,0)&"%","─") | J14: ☐

Sheet 📈 KPIs Business
A1: 📈 KPIs BUSINESS MENSUELS — WifiAudit AI & ORNET
A2: KPI / Indicateur | B2: Objectif | C2: Mai | D2: Juin | E2: Juil | F2: Août | G2: Sept | H2: Oct | I2: Nov | J2: Déc | K2: Total / Moy
A3: ── WIFIAUDIT AI ──
A4: Clients payants cumulés | B4: 15 fin Q4 | C4: 0 | D4: 1 | E4: 3 | F4: 5 | G4: 8 | H4: 10 | I4: 13 | J4: 15 | K4: =SUM(C4:J4)
A5: Nouveaux clients / mois | B5: 2+/mois | C5: 0 | D5: 1 | E5: 2 | F5: 2 | G5: 3 | H5: 2 | I5: 3 | J5: 2 | K5: =SUM(C5:J5)
A6: Revenus WifiAudit (€) | B6: 4485/mois | C6: 0 | D6: 299 | E6: 897 | F6: 1495 | G6: 2393 | H6: 2990 | I6: 3888 | J6: 4485 | K6: =SUM(C6:J6)
A7: Taux conversion waitlist % | B7: > 30% | C7: 0 | D7: 0 | E7: 10 | F7: 15 | G7: 20 | H7: 25 | I7: 28 | J7: 30 | K7: =SUM(C7:J7)
A8: Beta users actifs | B8: 10 | C8: 0 | D8: 0 | E8: 5 | F8: 7 | G8: 8 | H8: 9 | I8: 10 | J8: 10 | K8: =SUM(C8:J8)
A10: ── ORNET CONSULTING ──
A11: Appels découverte / mois | B11: 4+/mois | C11: 2 | D11: 3 | E11: 4 | F11: 4 | G11: 4 | H11: 3 | I11: 4 | J11: 3 | K11: =SUM(C11:J11)
A12: Devis envoyés / mois | B12: 3+/mois | C12: 1 | D12: 2 | E12: 3 | F12: 3 | G12: 3 | H12: 2 | I12: 3 | J12: 2 | K12: =SUM(C12:J12)
A13: Cas clients publiés (cumulés) | B13: 6 fin Q4 | C13: 0 | D13: 1 | E13: 2 | F13: 3 | G13: 4 | H13: 5 | I13: 6 | J13: 6 | K13: =SUM(C13:J13)
A14: Partenariats intégrateurs | B14: 1 signé Q3 | C14: 0 | D14: 0 | E14: 0 | F14: 0 | G14: 1 | H14: 1 | I14: 1 | J14: 1 | K14: =SUM(C14:J14)
A16: ── LINKEDIN & CONTENU ──
A17: Posts LinkedIn publiés | B17: 8/mois | C17: 3 | D17: 8 | E17: 8 | F17: 4 | G17: 8 | H17: 8 | I17: 8 | J17: 8 | K17: =SUM(C17:J17)
A18: Abonnés LinkedIn | B18: 700 fin Q4 | C18: 150 | D18: 200 | E18: 280 | F18: 320 | G18: 400 | H18: 480 | I18: 570 | J18: 700 | K18: =SUM(C18:J18)
A19: Articles or-net.com (cumulés) | B19: 12 fin Q4 | C19: 0 | D19: 1 | E19: 3 | F19: 5 | G19: 7 | H19: 8 | I19: 10 | J19: 12 | K19: =SUM(C19:J19)
A20: Newsletter envoyée | B20: 1/mois | C20: 0 | D20: 1 | E20: 1 | F20: 1 | G20: 1 | H20: 1 | I20: 1 | J20: 1 | K20: =SUM(C20:J20)
A22: ── FORMATION ──
A23: Notebooks Python créés | B23: 4+/mois | C23: 4 | D23: 4 | E23: 4 | F23: 2 | G23: 4 | H23: 4 | I23: 4 | J23: 4 | K23: =SUM(C23:J23)
A24: Labs EVE-NG SD-Access | B24: 2/mois | C24: 2 | D24: 2 | E24: 2 | F24: 1 | G24: 2 | H24: 2 | I24: 2 | J24: 1 | K24: =SUM(C24:J24)
A25: Sessions formation Théo/Alegria | B25: 4/mois | C25: 2 | D25: 4 | E25: 4 | F25: 4 | G25: 4 | H25: 4 | I25: 4 | J25: 4 | K25: =SUM(C25:J25)
A26: Score semaine moyen /10 | B26: > 7 | C26: 0 | D26: 0 | E26: 0 | F26: 0 | G26: 0 | H26: 0 | I26: 0 | J26: 0 | K26: =SUM(C26:J26)
A28: ── SANTÉ & ÉQUILIBRE ──
A29: Jours sport réalisés | B29: 25+/mois | C29: 15 | D29: 25 | E29: 25 | F29: 20 | G29: 25 | H29: 25 | I29: 25 | J29: 25 | K29: =SUM(C29:J29)
A30: Morning Agent jours actifs | B30: 30j/mois | C30: 15 | D30: 30 | E30: 31 | F30: 31 | G30: 30 | H30: 31 | I30: 30 | J30: 31 | K30: =SUM(C30:J30)

Sheet 🏃 Sport & Habitudes
A1: 🏃 TRACKER SPORT & HABITUDES QUOTIDIENNES
A2: Date | B2: Jour | C2: S# | D2: 🏃 Sport ✓ | E2: Type sport | F2: ⏱️ Durée | G2: 📚 Matin ✓ | H2: 🔧 Soir1 ✓ | I2: 🚀 Soir2 ✓ | J2: Note journée
A3: 12/05/26 | B3: Mar | C3: 1
A4: 13/05/26 | B4: Mer | C4: 1
A5: 14/05/26 | B5: Jeu | C5: 1
A6: 15/05/26 | B6: Ven | C6: 1
A7: 16/05/26 | B7: Sam | C7: 1
A8: 17/05/26 | B8: Dim | C8: 1
A9: 18/05/26 | B9: Lun | C9: 2
A10: 19/05/26 | B10: Mar | C10: 2
A11: 20/05/26 | B11: Mer | C11: 2
A12: 21/05/26 | B12: Jeu | C12: 2
A13: 22/05/26 | B13: Ven | C13: 2
A14: 23/05/26 | B14: Sam | C14: 2
... A44: 22/06/26 | B44: Lun | C44: 7
